[2022-02-03 20:26:41,623 : INFO : trainingValidationInsertion] - training data validation started...!
[2022-02-03 20:26:41,858 : INFO : trainingValidationInsertion] - Training data validation completed!
[2022-02-03 20:26:41,865 : ERROR : trainingValidationInsertion] - Error during training data validation : near "(": syntax error
Traceback (most recent call last):
  File "C:\Users\vishnu_nadh\Desktop\DS\MLDL\fck_prediction\DBoperarions\dbOperations.py", line 57, in createTableDb
    f'ALTER TABLE Good_Raw_Data ADD COLUMN "{key}" {type}'
sqlite3.OperationalError: no such table: Good_Raw_Data

During handling of the above exception, another exception occurred:

Traceback (most recent call last):
  File "C:\Users\vishnu_nadh\Desktop\DS\MLDL\fck_prediction\trainingValidationInsertion.py", line 35, in training_data_validation
    self.dboperation.createTableDb("Training", columnNames)
  File "C:\Users\vishnu_nadh\Desktop\DS\MLDL\fck_prediction\DBoperarions\dbOperations.py", line 71, in createTableDb
    raise e
  File "C:\Users\vishnu_nadh\Desktop\DS\MLDL\fck_prediction\DBoperarions\dbOperations.py", line 63, in createTableDb
    f"CREATE TABLE  Good_Raw_Data ({key} {type})")
sqlite3.OperationalError: near "(": syntax error
[2022-02-03 20:45:13,178 : INFO : trainingValidationInsertion] - training data validation started...!
[2022-02-03 20:45:14,562 : INFO : trainingValidationInsertion] - Training data validation completed!
[2022-02-03 20:45:14,885 : ERROR : trainingValidationInsertion] - Error during training data validation : near "(": syntax error
Traceback (most recent call last):
  File "C:\Users\vishnu_nadh\Desktop\DS\MLDL\fck_prediction\DBoperarions\dbOperations.py", line 57, in createTableDb
    f'ALTER TABLE Good_Raw_Data ADD COLUMN "{key}" {type}'
sqlite3.OperationalError: no such table: Good_Raw_Data

During handling of the above exception, another exception occurred:

Traceback (most recent call last):
  File "C:\Users\vishnu_nadh\Desktop\DS\MLDL\fck_prediction\trainingValidationInsertion.py", line 35, in training_data_validation
    self.dboperation.createTableDb("Training", columnNames)
  File "C:\Users\vishnu_nadh\Desktop\DS\MLDL\fck_prediction\DBoperarions\dbOperations.py", line 71, in createTableDb
    raise e
  File "C:\Users\vishnu_nadh\Desktop\DS\MLDL\fck_prediction\DBoperarions\dbOperations.py", line 63, in createTableDb
    f"CREATE TABLE  Good_Raw_Data ({key} {type})")
sqlite3.OperationalError: near "(": syntax error
[2022-02-03 20:47:18,995 : INFO : trainingValidationInsertion] - training data validation started...!
[2022-02-03 20:47:19,569 : INFO : trainingValidationInsertion] - Training data validation completed!
[2022-02-03 20:47:19,667 : ERROR : trainingValidationInsertion] - Error during training data validation : near "(": syntax error
Traceback (most recent call last):
  File "C:\Users\vishnu_nadh\Desktop\DS\MLDL\fck_prediction\DBoperarions\dbOperations.py", line 57, in createTableDb
    f'ALTER TABLE Good_Raw_Data ADD COLUMN "{key}" {type}'
sqlite3.OperationalError: no such table: Good_Raw_Data

During handling of the above exception, another exception occurred:

Traceback (most recent call last):
  File "C:\Users\vishnu_nadh\Desktop\DS\MLDL\fck_prediction\trainingValidationInsertion.py", line 35, in training_data_validation
    self.dboperation.createTableDb("Training", columnNames)
  File "C:\Users\vishnu_nadh\Desktop\DS\MLDL\fck_prediction\DBoperarions\dbOperations.py", line 71, in createTableDb
    raise e
  File "C:\Users\vishnu_nadh\Desktop\DS\MLDL\fck_prediction\DBoperarions\dbOperations.py", line 62, in createTableDb
    c.execute(f"CREATE TABLE  Good_Raw_Data ({key} {type})")
sqlite3.OperationalError: near "(": syntax error
[2022-02-03 20:48:19,768 : INFO : trainingValidationInsertion] - training data validation started...!
[2022-02-03 20:48:21,713 : INFO : trainingValidationInsertion] - Training data validation completed!
[2022-02-03 20:48:22,153 : ERROR : trainingValidationInsertion] - Error during training data validation : near "(": syntax error
Traceback (most recent call last):
  File "C:\Users\vishnu_nadh\Desktop\DS\MLDL\fck_prediction\DBoperarions\dbOperations.py", line 57, in createTableDb
    f'ALTER TABLE Good_Raw_Data ADD COLUMN "{key}" {type}'
sqlite3.OperationalError: no such table: Good_Raw_Data

During handling of the above exception, another exception occurred:

Traceback (most recent call last):
  File "C:\Users\vishnu_nadh\Desktop\DS\MLDL\fck_prediction\trainingValidationInsertion.py", line 35, in training_data_validation
    self.dboperation.createTableDb("Training", columnNames)
  File "C:\Users\vishnu_nadh\Desktop\DS\MLDL\fck_prediction\DBoperarions\dbOperations.py", line 72, in createTableDb
    raise e
  File "C:\Users\vishnu_nadh\Desktop\DS\MLDL\fck_prediction\DBoperarions\dbOperations.py", line 64, in createTableDb
    c.execute(f"CREATE TABLE  Good_Raw_Data ({key} {type})")
sqlite3.OperationalError: near "(": syntax error
[2022-02-03 20:51:34,205 : INFO : trainingValidationInsertion] - training data validation started...!
[2022-02-03 20:51:34,808 : INFO : trainingValidationInsertion] - Training data validation completed!
[2022-02-03 20:51:34,935 : ERROR : trainingValidationInsertion] - Error during training data validation : near "(": syntax error
Traceback (most recent call last):
  File "C:\Users\vishnu_nadh\Desktop\DS\MLDL\fck_prediction\DBoperarions\dbOperations.py", line 58, in createTableDb
    f'ALTER TABLE Good_Raw_Data ADD COLUMN "{key}" {type}'
sqlite3.OperationalError: no such table: Good_Raw_Data

During handling of the above exception, another exception occurred:

Traceback (most recent call last):
  File "C:\Users\vishnu_nadh\Desktop\DS\MLDL\fck_prediction\trainingValidationInsertion.py", line 35, in training_data_validation
    self.dboperation.createTableDb("Training", columnNames)
  File "C:\Users\vishnu_nadh\Desktop\DS\MLDL\fck_prediction\DBoperarions\dbOperations.py", line 71, in createTableDb
    raise e
  File "C:\Users\vishnu_nadh\Desktop\DS\MLDL\fck_prediction\DBoperarions\dbOperations.py", line 63, in createTableDb
    c.execute(f"CREATE TABLE  Good_Raw_Data ({key} {type})")
sqlite3.OperationalError: near "(": syntax error
[2022-02-03 20:56:14,749 : INFO : trainingValidationInsertion] - training data validation started...!
[2022-02-03 20:56:14,969 : INFO : trainingValidationInsertion] - Training data validation completed!
[2022-02-03 20:56:14,975 : ERROR : trainingValidationInsertion] - Error during training data validation : near "(": syntax error
Traceback (most recent call last):
  File "C:\Users\vishnu_nadh\Desktop\DS\MLDL\fck_prediction\DBoperarions\dbOperations.py", line 58, in createTableDb
    column_name=key, dataType=type
sqlite3.OperationalError: no such table: Good_Raw_Data

During handling of the above exception, another exception occurred:

Traceback (most recent call last):
  File "C:\Users\vishnu_nadh\Desktop\DS\MLDL\fck_prediction\trainingValidationInsertion.py", line 35, in training_data_validation
    self.dboperation.createTableDb("Training", columnNames)
  File "C:\Users\vishnu_nadh\Desktop\DS\MLDL\fck_prediction\DBoperarions\dbOperations.py", line 74, in createTableDb
    raise e
  File "C:\Users\vishnu_nadh\Desktop\DS\MLDL\fck_prediction\DBoperarions\dbOperations.py", line 66, in createTableDb
    column_name=key, dataType=type
sqlite3.OperationalError: near "(": syntax error
[2022-02-03 21:25:04,275 : INFO : trainingValidationInsertion] - training data validation started...!
[2022-02-03 21:25:04,548 : INFO : trainingValidationInsertion] - Training data validation completed!
[2022-02-03 21:25:04,559 : ERROR : trainingValidationInsertion] - Error during training data validation : near "(": syntax error
Traceback (most recent call last):
  File "C:\Users\vishnu_nadh\Desktop\DS\MLDL\fck_prediction\DBoperarions\dbOperations.py", line 59, in createTableDb
    column_name=key, dataType=type
sqlite3.OperationalError: no such table: Good_Raw_Data

During handling of the above exception, another exception occurred:

Traceback (most recent call last):
  File "C:\Users\vishnu_nadh\Desktop\DS\MLDL\fck_prediction\trainingValidationInsertion.py", line 35, in training_data_validation
    self.dboperation.createTableDb("Training", columnNames)
  File "C:\Users\vishnu_nadh\Desktop\DS\MLDL\fck_prediction\DBoperarions\dbOperations.py", line 75, in createTableDb
    raise e
  File "C:\Users\vishnu_nadh\Desktop\DS\MLDL\fck_prediction\DBoperarions\dbOperations.py", line 69, in createTableDb
    conn.execute(query)
sqlite3.OperationalError: near "(": syntax error
[2022-02-03 21:27:27,963 : INFO : trainingValidationInsertion] - training data validation started...!
[2022-02-03 21:27:28,295 : INFO : trainingValidationInsertion] - Training data validation completed!
[2022-02-03 21:27:28,317 : ERROR : trainingValidationInsertion] - Error during training data validation : log() missing 1 required positional argument: 'msg'
Traceback (most recent call last):
  File "C:\Users\vishnu_nadh\Desktop\DS\MLDL\fck_prediction\DBoperarions\dbOperations.py", line 59, in createTableDb
    column_name=key, dataType=type
sqlite3.OperationalError: no such table: Good_Raw_Data

During handling of the above exception, another exception occurred:

Traceback (most recent call last):
  File "C:\Users\vishnu_nadh\Desktop\DS\MLDL\fck_prediction\trainingValidationInsertion.py", line 35, in training_data_validation
    self.dboperation.createTableDb("Training", columnNames)
  File "C:\Users\vishnu_nadh\Desktop\DS\MLDL\fck_prediction\DBoperarions\dbOperations.py", line 75, in createTableDb
    raise e
  File "C:\Users\vishnu_nadh\Desktop\DS\MLDL\fck_prediction\DBoperarions\dbOperations.py", line 68, in createTableDb
    logger.log(query)
TypeError: log() missing 1 required positional argument: 'msg'
[2022-02-03 21:28:05,719 : INFO : trainingValidationInsertion] - training data validation started...!
[2022-02-03 21:28:05,994 : INFO : trainingValidationInsertion] - Training data validation completed!
[2022-02-03 21:28:06,000 : ERROR : trainingValidationInsertion] - Error during training data validation : near "(": syntax error
Traceback (most recent call last):
  File "C:\Users\vishnu_nadh\Desktop\DS\MLDL\fck_prediction\DBoperarions\dbOperations.py", line 59, in createTableDb
    column_name=key, dataType=type
sqlite3.OperationalError: no such table: Good_Raw_Data

During handling of the above exception, another exception occurred:

Traceback (most recent call last):
  File "C:\Users\vishnu_nadh\Desktop\DS\MLDL\fck_prediction\trainingValidationInsertion.py", line 35, in training_data_validation
    self.dboperation.createTableDb("Training", columnNames)
  File "C:\Users\vishnu_nadh\Desktop\DS\MLDL\fck_prediction\DBoperarions\dbOperations.py", line 75, in createTableDb
    raise e
  File "C:\Users\vishnu_nadh\Desktop\DS\MLDL\fck_prediction\DBoperarions\dbOperations.py", line 69, in createTableDb
    conn.execute(query)
sqlite3.OperationalError: near "(": syntax error
[2022-02-03 22:06:21,111 : INFO : trainingValidationInsertion] - training data validation started...!
[2022-02-03 22:06:21,420 : INFO : trainingValidationInsertion] - Training data validation completed!
[2022-02-03 22:06:21,567 : INFO : trainingValidationInsertion] - Table creation completed
[2022-02-03 22:08:22,786 : INFO : trainingValidationInsertion] - training data validation started...!
[2022-02-03 22:08:22,943 : INFO : trainingValidationInsertion] - Training data validation completed!
[2022-02-03 22:08:22,945 : INFO : trainingValidationInsertion] - Table creation completed
[2022-02-03 22:10:59,333 : INFO : trainingValidationInsertion] - training data validation started...!
[2022-02-03 22:10:59,479 : INFO : trainingValidationInsertion] - Training data validation completed!
[2022-02-03 22:10:59,482 : INFO : trainingValidationInsertion] - Table creation completed
[2022-02-03 23:41:06,766 : INFO : trainingValidationInsertion] - training data validation started...!
[2022-02-03 23:41:07,094 : INFO : trainingValidationInsertion] - Training data validation completed!
[2022-02-03 23:41:07,106 : INFO : trainingValidationInsertion] - Table creation completed
[2022-02-03 23:44:24,268 : INFO : trainingValidationInsertion] - training data validation started...!
[2022-02-03 23:44:24,513 : INFO : trainingValidationInsertion] - Training data validation completed!
[2022-02-03 23:44:24,517 : INFO : trainingValidationInsertion] - Table creation completed
[2022-02-03 23:47:02,505 : INFO : trainingValidationInsertion] - training data validation started...!
[2022-02-03 23:47:02,915 : INFO : trainingValidationInsertion] - Training data validation completed!
[2022-02-03 23:47:02,921 : INFO : trainingValidationInsertion] - Table creation completed
[2022-02-03 23:51:43,329 : INFO : trainingValidationInsertion] - training data validation started...!
[2022-02-03 23:51:43,725 : INFO : trainingValidationInsertion] - Training data validation completed!
[2022-02-03 23:51:43,735 : INFO : trainingValidationInsertion] - Table creation completed
[2022-02-03 23:52:15,301 : INFO : trainingValidationInsertion] - csv data inserted into database table
[2022-02-04 00:30:41,452 : INFO : trainingValidationInsertion] - training data validation started...!
[2022-02-04 00:30:41,756 : INFO : trainingValidationInsertion] - Training data validation completed!
[2022-02-04 00:30:41,776 : INFO : trainingValidationInsertion] - Table creation completed
[2022-02-04 00:31:15,716 : INFO : trainingValidationInsertion] - csv data inserted into database table
[2022-02-04 00:31:15,719 : INFO : trainingValidationInsertion] - Deleted good data folder
[2022-02-04 00:31:15,719 : ERROR : trainingValidationInsertion] - Error during training data validation : moveBadDataToArchiveBad() takes 0 positional arguments but 1 was given
Traceback (most recent call last):
  File "C:\Users\vishnu_nadh\Desktop\DS\MLDL\fck_prediction\trainingValidationInsertion.py", line 44, in training_data_validation
    self.raw_data_validation.moveBadDataToArchiveBad()
TypeError: moveBadDataToArchiveBad() takes 0 positional arguments but 1 was given
[2022-02-04 00:33:49,692 : INFO : trainingValidationInsertion] - training data validation started...!
[2022-02-04 00:33:49,943 : INFO : trainingValidationInsertion] - Training data validation completed!
[2022-02-04 00:33:49,951 : INFO : trainingValidationInsertion] - Table creation completed
[2022-02-04 00:34:09,911 : INFO : trainingValidationInsertion] - csv data inserted into database table
[2022-02-04 00:34:09,913 : INFO : trainingValidationInsertion] - Deleted good data folder
[2022-02-04 00:34:09,913 : ERROR : trainingValidationInsertion] - Error during training data validation : module 'datetime' has no attribute 'now'
Traceback (most recent call last):
  File "C:\Users\vishnu_nadh\Desktop\DS\MLDL\fck_prediction\trainingValidationInsertion.py", line 44, in training_data_validation
    self.raw_data_validation.moveBadDataToArchiveBad()
  File "C:\Users\vishnu_nadh\Desktop\DS\MLDL\fck_prediction\Training_Rawdata_Validation\rawValidation.py", line 99, in moveBadDataToArchiveBad
    now = datetime.now()
AttributeError: module 'datetime' has no attribute 'now'
[2022-02-04 00:35:13,934 : INFO : trainingValidationInsertion] - training data validation started...!
[2022-02-04 00:35:14,606 : INFO : trainingValidationInsertion] - Training data validation completed!
[2022-02-04 00:35:14,669 : INFO : trainingValidationInsertion] - Table creation completed
[2022-02-04 00:35:41,666 : INFO : trainingValidationInsertion] - csv data inserted into database table
[2022-02-04 00:35:41,667 : INFO : trainingValidationInsertion] - Deleted good data folder
[2022-02-04 00:35:41,724 : ERROR : trainingValidationInsertion] - Error during training data validation : 'Logger' object has no attribute 'ingo'
Traceback (most recent call last):
  File "C:\Users\vishnu_nadh\Desktop\DS\MLDL\fck_prediction\trainingValidationInsertion.py", line 45, in training_data_validation
    logger.ingo("bad data files moved to archived folder")
AttributeError: 'Logger' object has no attribute 'ingo'
[2022-02-04 00:37:05,842 : INFO : trainingValidationInsertion] - training data validation started...!
[2022-02-04 00:37:06,180 : INFO : trainingValidationInsertion] - Training data validation completed!
[2022-02-04 00:37:06,475 : INFO : trainingValidationInsertion] - Table creation completed
[2022-02-04 00:37:35,114 : INFO : trainingValidationInsertion] - csv data inserted into database table
[2022-02-04 00:37:35,115 : INFO : trainingValidationInsertion] - Deleted good data folder
[2022-02-04 00:37:35,147 : INFO : trainingValidationInsertion] - bad data files moved to archived folder
[2022-02-04 01:02:06,870 : INFO : trainingValidationInsertion] - training data validation started...!
[2022-02-04 01:02:07,284 : INFO : trainingValidationInsertion] - Training data validation completed!
[2022-02-04 01:02:07,331 : INFO : trainingValidationInsertion] - Table creation completed
[2022-02-04 01:02:26,609 : INFO : trainingValidationInsertion] - csv data inserted into database table
[2022-02-04 01:02:26,611 : INFO : trainingValidationInsertion] - Deleted good data folder
[2022-02-04 01:02:26,644 : INFO : trainingValidationInsertion] - bad data files moved to archived folder
[2022-02-04 01:02:26,765 : INFO : trainingValidationInsertion] - databse data exported to csv succussfully
[2022-02-04 10:31:38,023 : INFO : trainingValidationInsertion] - training data validation started...!
[2022-02-04 10:31:38,168 : INFO : trainingValidationInsertion] - Training data validation completed!
[2022-02-04 10:31:38,171 : INFO : trainingValidationInsertion] - Table creation completed
[2022-02-04 10:31:38,172 : INFO : trainingValidationInsertion] - Deleted table content from db before adding new data
[2022-02-04 10:31:56,614 : INFO : trainingValidationInsertion] - csv data inserted into database table
[2022-02-04 10:31:56,616 : INFO : trainingValidationInsertion] - Deleted good data folder
[2022-02-04 10:31:56,649 : INFO : trainingValidationInsertion] - bad data files moved to archived folder
[2022-02-04 10:31:56,767 : INFO : trainingValidationInsertion] - databse data exported to csv succussfully
[2022-02-04 10:35:09,673 : INFO : trainingValidationInsertion] - training data validation started...!
[2022-02-04 10:35:09,818 : INFO : trainingValidationInsertion] - Training data validation completed!
[2022-02-04 10:35:09,821 : INFO : trainingValidationInsertion] - Table creation completed
[2022-02-04 10:35:09,822 : INFO : trainingValidationInsertion] - Deleted table content from db before adding new data
[2022-02-04 10:35:21,090 : INFO : trainingValidationInsertion] - csv data inserted into database table
[2022-02-04 10:35:21,092 : INFO : trainingValidationInsertion] - Deleted good data folder
[2022-02-04 10:35:21,111 : INFO : trainingValidationInsertion] - bad data files moved to archived folder
[2022-02-04 10:35:21,153 : INFO : trainingValidationInsertion] - databse data exported to csv succussfully
[2022-02-04 10:38:24,690 : INFO : trainingValidationInsertion] - training data validation started...!
[2022-02-04 10:38:24,809 : INFO : trainingValidationInsertion] - Training data validation completed!
[2022-02-04 10:38:24,814 : INFO : trainingValidationInsertion] - Table creation completed
[2022-02-04 10:38:24,818 : ERROR : trainingValidationInsertion] - Error during training data validation : 'NoneType' object is not subscriptable
Traceback (most recent call last):
  File "C:\Users\vishnu_nadh\Desktop\DS\MLDL\fck_prediction\trainingValidationInsertion.py", line 41, in training_data_validation
    self.dboperation.deleteTableContentFromDB("Training")
  File "C:\Users\vishnu_nadh\Desktop\DS\MLDL\fck_prediction\DBoperarions\dbOperations.py", line 103, in deleteTableContentFromDB
    raise e
  File "C:\Users\vishnu_nadh\Desktop\DS\MLDL\fck_prediction\DBoperarions\dbOperations.py", line 94, in deleteTableContentFromDB
    if c.fetchone()[0] != 1:  # table is not empty
TypeError: 'NoneType' object is not subscriptable
[2022-02-04 10:46:05,498 : INFO : trainingValidationInsertion] - training data validation started...!
[2022-02-04 10:46:05,614 : INFO : trainingValidationInsertion] - Training data validation completed!
[2022-02-04 10:46:05,619 : INFO : trainingValidationInsertion] - Table creation completed
[2022-02-04 10:46:05,620 : INFO : trainingValidationInsertion] - Deleted table content from db before adding new data
[2022-02-04 10:46:19,310 : INFO : trainingValidationInsertion] - csv data inserted into database table
[2022-02-04 10:46:19,312 : INFO : trainingValidationInsertion] - Deleted good data folder
[2022-02-04 10:46:19,336 : INFO : trainingValidationInsertion] - bad data files moved to archived folder
[2022-02-04 10:46:19,527 : INFO : trainingValidationInsertion] - databse data exported to csv succussfully
[2022-02-04 10:56:20,174 : INFO : trainingValidationInsertion] - training data validation started...!
[2022-02-04 10:56:20,310 : INFO : trainingValidationInsertion] - Training data validation completed!
[2022-02-04 10:56:20,313 : INFO : trainingValidationInsertion] - Table creation completed
[2022-02-04 10:56:20,327 : INFO : trainingValidationInsertion] - Deleted table content from db before adding new data
[2022-02-04 10:56:38,472 : INFO : trainingValidationInsertion] - csv data inserted into database table
[2022-02-04 10:56:38,474 : INFO : trainingValidationInsertion] - Deleted good data folder
[2022-02-04 10:56:38,507 : INFO : trainingValidationInsertion] - bad data files moved to archived folder
[2022-02-04 10:56:38,526 : INFO : trainingValidationInsertion] - databse data exported to csv succussfully
[2022-02-04 11:00:24,988 : INFO : trainingValidationInsertion] - training data validation started...!
[2022-02-04 11:00:25,123 : INFO : trainingValidationInsertion] - Training data validation completed!
[2022-02-04 11:00:25,128 : INFO : trainingValidationInsertion] - Table creation completed
[2022-02-04 11:00:25,141 : INFO : trainingValidationInsertion] - Deleted table content from db before adding new data
[2022-02-04 11:00:37,861 : INFO : trainingValidationInsertion] - csv data inserted into database table
[2022-02-04 11:00:37,863 : INFO : trainingValidationInsertion] - Deleted good data folder
[2022-02-04 11:00:37,928 : INFO : trainingValidationInsertion] - bad data files moved to archived folder
[2022-02-04 11:00:37,960 : INFO : trainingValidationInsertion] - databse data exported to csv succussfully
